<mujoco model="sphere">  
    <compiler  meshdir='obj'/>
    <asset>
        <material name="spherebody"  texuniform="true" rgba="0 1 0 1"
            reflectance="0.8" shininess="0.9"/>
        <material name="hoopbody"  texuniform="true" rgba="1 1 0 1"
            reflectance="0.8" shininess="0.9"/>
        <mesh name="hoop" file="hoop.obj" scale="0.1 0.1 0.1"/>
    </asset>
    <worldbody> 
        <body name="obstacle" pos='1 0 1.6' euler="0 0 0">
            <joint name="obstacle" type="slide" limited="true" pos="2 0 1.2" axis='1 0 0' range='-4 2'/> 
            <geom type="sphere" name="green_sphere" pos="0 0 0" size="0.15"  material="spherebody" class="collision"/>  
        </body>
        <body name="hoop" pos='0.5 -0.5 1.3' euler="0 0 90">
            <joint name="passive"   limited="false" pos="0 0 0" axis='1 0 0'  /> 
            <geom type='mesh' mesh='hoop' pos='0 0 0'  euler='-0 0 -0'   material="hoopbody" />  
        </body>
    </worldbody> 
  <actuator>
        <motor name='obstacle' joint='obstacle' gear='50' ctrllimited='false' ctrlrange='-1 1' />
  </actuator>
  
</mujoco>
