<mujoco model="planar manipulator">
  

  <visual>
    <map shadowclip=".5"/>
    <quality shadowsize="2048"/>
  </visual>>

  <option timestep="0.001" cone="elliptic"/>

  <default>
    <!-- <geom friction=".7" solimp="0.9 0.97 0.001" solref=".005 1"/> -->
    <!-- <joint solimplimit="0 0.99 0.01" solreflimit=".005 1"/> -->
    <general ctrllimited="true"/>
    <tendon width="0.01"/>
    <site size=".003 .003 .003"  group="3"/>

    <default class="arm">
      <geom type="capsule"  density="500"/>
      <joint type="hinge" pos="0 0 0" axis="0 -1 0" limited="true"/>
      <default class="hand">
        <joint damping=".5" range="-10 60"/>
        <geom size=".008"/>
        <site  type="box" size=".018 .005 .005" pos=".022 0 -.002" euler="0 15 0" group="4"/>
        <default class="fingertip">
          <geom type="sphere" size=".008"  />
          <joint damping=".01" stiffness=".01" range="-40 20"/>
          <site  size=".012 .005 .008" pos=".003 0 .003" group="4" euler="0 0 0"/>
        </default>
      </default>
    </default>

    <default class="object"> 
    </default>

    <default class="task">
      <site rgba="0 0 0 0"/>
    </default>

    <default class="obstacle">
      <geom  friction="0"/>
    </default>

    <default class="ghost">
      <geom   contype="0" conaffinity="0"/>
    </default>
  </default>

  <worldbody> 

    <!-- Arm --> 
    <body  name="hand" pos="0 0 .12" childclass="arm">
        <joint name="arm_wrist" damping="0.5" range="-140 140" />
        <geom  name="hand" size=".011" fromto="0 0 0 0 0 .03"/>
        <geom  name="palm1"  fromto="0 0 .03  .03 0 .045" class="hand"/>
        <geom  name="palm2"  fromto="0 0 .03 -.03 0 .045" class="hand"/>
        <site  name="grasp" pos="0 0 .065"/>
        <body  name="pinch site" pos="0 0 .090">
            <site  name="pinch"/>
            <inertial pos="0 0 0" mass="1e-6" diaginertia="1e-12 1e-12 1e-12"/>
            <camera name="hand" pos="0 -.3 0" xyaxes="1 0 0 0 0 1" mode="track"/>
        </body>
        <site  name="palm_touch" type="box" group="4" size=".025 .005 .008" pos="0 0 .043"/>

        <body name="thumb" pos=".03 0 .045" euler="0 -90 0" childclass="hand">
            <joint name="thumb"/>
            <geom  name="thumb1"  fromto="0 0 0 .08 0.0 -.07" size=".007"/>
            <geom  name="thumb2"  fromto=".08 0.0 -.07 .16 0.0 -.07" size=".007"/>
            <site  name="thumb_touch" group="4"/>
            <body  name="thumbtip" pos=".17 0.0 -.07" childclass="fingertip">
                <joint name="thumbtip"/>
                <geom  name="thumbtip1" pos="-.003 0 0" />
                <geom  name="thumbtip2" pos=".003 0 0" />
                <site  name="thumbtip_touch" group="4"/>
            </body>
        </body>

        <body name="finger" pos="-.03 0 .045" euler="0 90 180" childclass="hand">
            <joint name="finger"/>
            <geom  name="finger1"  fromto="0 0 0 .08 0.0 -.07" size=".007" />
            <geom  name="finger2"  fromto=".08 0.0 -.07 .16 0.0 -.07" size=".007"/>
            <site  name="finger_touch"/>
            <body  name="fingertip" pos=".17 0.0 -.07" childclass="fingertip">
                <joint name="fingertip"/>
                <geom  name="fingertip1" pos="-.003 0 0" />
                <geom  name="fingertip2" pos=".003 0 0" />
                <site  name="fingertip_touch"/>
            </body>
        </body> 
    </body>
   

  </worldbody>

  <tendon>
    <fixed name="grasp">
      <joint joint="thumb"  coef=".5"/>
      <joint joint="finger" coef=".5"/>
    </fixed>
    <fixed name="coupling">
      <joint joint="thumb"  coef="-.5"/>
      <joint joint="finger" coef=".5"/>
    </fixed>
  </tendon>

  <equality>
    <tendon name="coupling" tendon1="coupling" solimp="0.95 0.99 0.001" solref=".005 .5"/>
  </equality>

  <sensor>
    <touch name="palm_touch" site="palm_touch"/>
    <touch name="finger_touch" site="finger_touch"/>
    <touch name="thumb_touch" site="thumb_touch"/>
    <touch name="fingertip_touch" site="fingertip_touch"/>
    <touch name="thumbtip_touch" site="thumbtip_touch"/>
  </sensor>

  <actuator>
    <!-- <motor name="root"     joint="arm_root"     ctrlrange="-1 1"  gear="12"/> -->
    <!-- <motor name="shoulder" joint="arm_shoulder" ctrlrange="-1 1"  gear="8"/> -->
    <!-- <motor name="elbow"    joint="arm_elbow"    ctrlrange="-1 1"  gear="4"/> -->
    <motor name="wrist"    joint="arm_wrist" ctrlrange="-1 1"  gear="2"/>
    <motor name="grasp"    tendon="grasp"       ctrlrange="-1 1"  gear="2"/>
  </actuator>

</mujoco>