<mujoco model="sphere">  
    <compiler  meshdir='obj'/>
    <asset>
        <material name="spherebody"  texuniform="true" rgba="1 0.647 0 1"
            reflectance="0.8" shininess="0.9"/>  
    </asset>
    <worldbody> 
        <body name="obstacle" pos='1 0 1.57' euler="0 0 0">
            <joint name="obstacle" type="slide" limited="true" pos="2 0 1.2" axis='1 0 0' range='-4 2'/> 
            <geom type="sphere" name="green_sphere" pos="0 0 0" size="0.12" mass="0.62369" material="spherebody" class="collision"/>  
        </body> 
    </worldbody> 
  <actuator>
        <motor name='obstacle' joint='obstacle' gear='50' ctrllimited='false' ctrlrange='-1 1' />
  </actuator>
  
</mujoco>
